22:52:28 - INFO - eir.train_utils.utils - Global random seed set to 0.
Traceback (most recent call last):
  File "/home/panwei/he000176/.conda/envs/eir-gln/bin/eirtrain", line 8, in <module>
    sys.exit(main())
             ^^^^^^
  File "/home/panwei/he000176/.conda/envs/eir-gln/lib/python3.11/site-packages/eir/train.py", line 65, in main
    configs = get_configs()
              ^^^^^^^^^^^^^
  File "/home/panwei/he000176/.conda/envs/eir-gln/lib/python3.11/site-packages/eir/setup/config.py", line 120, in get_configs
    configs = generate_aggregated_config(
              ^^^^^^^^^^^^^^^^^^^^^^^^^^^
  File "/home/panwei/he000176/.conda/envs/eir-gln/lib/python3.11/site-packages/eir/setup/config.py", line 266, in generate_aggregated_config
    output_configs = load_output_configs(output_configs=output_config_iter)
                     ^^^^^^^^^^^^^^^^^^^^^^^^^^^^^^^^^^^^^^^^^^^^^^^^^^^^^^
  File "/home/panwei/he000176/.conda/envs/eir-gln/lib/python3.11/site-packages/eir/setup/config.py", line 670, in load_output_configs
    config_object = init_output_config(
                    ^^^^^^^^^^^^^^^^^^^
  File "/home/panwei/he000176/.conda/envs/eir-gln/lib/python3.11/site-packages/eir/setup/config.py", line 697, in init_output_config
    validate_keys_against_dataclass(
  File "/home/panwei/he000176/.conda/envs/eir-gln/lib/python3.11/site-packages/eir/setup/config.py", line 369, in validate_keys_against_dataclass
    raise KeyError(message)
KeyError: "Unexpected keys found in configuration: 'model_type, label_file, target_cat_columns, target_con_columns, label_parsing_chunk_size'. Expected keys of type 'OutputConfig': 'output_type_info, sampling_config, output_info, model_config'."
